Workbook

Sheet PW001
C1: Suivi Opération Pw001
A5: Operation Date | B5: Operation | C5: Serre | D5: Sup | E5: Trage Transport | F5: EQUPE | G5: type operation | H5: Type Ouvrier | I5: Nb Ouvrier | J5: Prix/Ouvrier | K5: Total | L5: prix/trage | M5: Prix Transport | N5: TOTAL
A6: 45761 | B6: RECOLTE | C6: 123 | D6: {=IFERROR(_xlfn.XLOOKUP(C6,Code!A:A,Code!B:B),"")} -> 0.88 | E6: NOUREDDINE | G6: JRS | H6: ouvrier | I6: 8 | J6: 180 | K6: =I6*J6 -> 1440
B7: RECOLTE | C7: 123 | G7: JRS | H7: Caporale | I7: 1 | J7: 180 | K7: =I7*J7 -> 180
B8: RECOLTE | C8: 124 | D8: {=IFERROR(_xlfn.XLOOKUP(C8,Code!A:A,Code!B:B),"")} -> 0.95 | E8: EL YOUSSFI | G8: JRS | H8: ouvrier | I8: 29 | J8: 180 | K8: =I8*J8 -> 5220
B9: RECOLTE | G9: JRS | H9: Caporale | I9: 1 | J9: 180 | K9: =I9*J9 -> 180
B10: RECOLTE | C10: 127 | D10: {=IFERROR(_xlfn.XLOOKUP(C10,Code!A:A,Code!B:B),"")} -> 0.95 | G10: JRS | H10: ouvrier | I10: 24 | J10: 180 | K10: =I10*J10 -> 4320
B11: RECOLTE | G11: JRS | H11: Caporale | I11: 1 | J11: 180 | K11: =I11*J11 -> 180
A12: 45762 | B12: RECOLTE | C12: 123 | D12: {=IFERROR(_xlfn.XLOOKUP(C12,Code!A:A,Code!B:B),"")} -> 0.88 | E12: NOUREDDINE | G12: JRS | H12: ouvrier | I12: 13 | J12: 180 | K12: =I12*J12 -> 2340
B13: RECOLTE | C13: 116 | G13: JRS | H13: Caporale | I13: 1 | J13: 180 | K13: =I13*J13 -> 180
B14: RECOLTE | C14: 124 | D14: {=IFERROR(_xlfn.XLOOKUP(C14,Code!A:A,Code!B:B),"")} -> 0.95 | E14: EL YOUSSFI | G14: JRS | H14: ouvrier | I14: 39 | J14: 180 | K14: =I14*J14 -> 7020
B15: RECOLTE | C15: 124 | G15: JRS | H15: Caporale | I15: 1 | J15: 180 | K15: =I15*J15 -> 180
B16: RECOLTE | C16: 127 | D16: {=IFERROR(_xlfn.XLOOKUP(C16,Code!A:A,Code!B:B),"")} -> 0.95 | G16: JRS | H16: ouvrier | I16: 40 | J16: 180 | K16: =I16*J16 -> 7200
B17: RECOLTE | C17: 127 | G17: JRS | H17: Caporale | I17: 1 | J17: 180 | K17: =I17*J17 -> 180
A18: 46131 | B18: SELECTION | C18: 126 | D18: {=IFERROR(_xlfn.XLOOKUP(C18,Code!A:A,Code!B:B),"")} -> 0.95 | E18: AIT AMIRA | F18: BELAID (HAFIDA) | G18: JRS | H18: ouvrier | I18: 20 | J18: 100 | K18: 2000 | L18: 25 | M18: 525
G19: JRS | H19: Caporale | I19: 1 | J19: 120 | K19: 120 | L19: 25
A20: 46132 | B20: SELECTION | C20: 126 | D20: {=IFERROR(_xlfn.XLOOKUP(C20,Code!A:A,Code!B:B),"")} -> 0.95 | E20: AIT AMIRA | F20: BELAID (HAFIDA) | G20: JRS | H20: Caporale | I20: 1 | J20: 120 | K20: 120 | L20: 25 | M20: 525
G21: JRS | H21: ouvrier | I21: 20 | J21: 100 | K21: 2000 | L21: 25
A22: 46133 | B22: SELECTION | C22: 132 | D22: {=IFERROR(_xlfn.XLOOKUP(C22,Code!A:A,Code!B:B),"")} -> 0.95 | E22: AIT AMIRA | F22: BELAID (HAFIDA) | G22: JRS | H22: ouvrier | I22: 15 | J22: 100 | K22: 1500 | L22: 25 | M22: 375
A23: 46134 | B23: RECOLTE | C23: 129 | D23: {=IFERROR(_xlfn.XLOOKUP(C23,Code!A:A,Code!B:B),"")} -> 0.96 | E23: AIT AMIRA | F23: BELAID (HAFIDA) | G23: JRS | H23: ouvrier | I23: 18 | J23: 100 | K23: 1800 | L23: 25 | M23: 475
G24: JRS | H24: Caporale | I24: 1 | J24: 120 | K24: 120 | L24: 25
B25: SELECTION | C25: 131 | D25: {=IFERROR(_xlfn.XLOOKUP(C25,Code!A:A,Code!B:B),"")} -> 0.96 | F25: BELAID(NEZHA) | G25: JRS | H25: ouvrier | I25: 13 | J25: 100 | K25: 1300 | L25: 25 | M25: 350
G26: JRS | H26: Caporale | I26: 1 | J26: 120 | K26: 120 | L26: 25
A27: 46135 | B27: RECOLTE | C27: 131 | D27: {=IFERROR(_xlfn.XLOOKUP(C27,Code!A:A,Code!B:B),"")} -> 0.96 | F27: BELAID(NEZHA) | G27: JRS | H27: ouvrier | I27: 12 | J27: 100 | K27: 1200 | L27: 25 | M27: 325
G28: JRS | H28: Caporale | I28: 1 | J28: 120 | K28: 120 | L28: 25
B29: RECOLTE | C29: 129 | D29: {=IFERROR(_xlfn.XLOOKUP(C29,Code!A:A,Code!B:B),"")} -> 0.96 | E29: AIT AMIRA | F29: BELAID (HAFIDA) | G29: JRS | H29: ouvrier | I29: 22 | J29: 100 | K29: 2200 | L29: 25 | M29: 550
G30: JRS | H30: Caporale | I30: 1 | J30: 120 | K30: 120 | L30: 25
B31: RECOLTE | C31: 112 | D31: {=IFERROR(_xlfn.XLOOKUP(C31,Code!A:A,Code!B:B),"")} -> 0.96 | F31: BELAID (kamal) | G31: JRS | H31: ouvrier | I31: 16 | J31: 100 | K31: 1600 | L31: 25 | M31: 425
G32: JRS | H32: Caporale | I32: 1 | J32: 120 | K32: 120 | L32: 25
C33: 113 | D33: {=IFERROR(_xlfn.XLOOKUP(C33,Code!A:A,Code!B:B),"")} -> 1.32 | F33: DRISS(SABAH) | G33: JRS | H33: ouvrier | I33: 15
G34: JRS | H34: Caporale | I34: 1
B35: SELECTION | C35: 124 | D35: {=IFERROR(_xlfn.XLOOKUP(C35,Code!A:A,Code!B:B),"")} -> 0.95 | F35: DRISS(milouda) | G35: JRS | H35: ouvrier | I35: 17
G36: JRS | H36: Caporale | I36: 1
B37: SELECTION | C37: 105 | D37: {=IFERROR(_xlfn.XLOOKUP(C37,Code!A:A,Code!B:B),"")} -> 0.95 | F37: BELAID(ABDELGHANI) | G37: JRS | H37: ouvrier | I37: 10 | J37: 100 | K37: 1000 | L37: 25 | M37: 275
G38: JRS | H38: Caporale | I38: 1 | J38: 120 | K38: 120 | L38: 25
A39: 24/42026 | B39: RECOLTE | C39: 126 | D39: {=IFERROR(_xlfn.XLOOKUP(C39,Code!A:A,Code!B:B),"")} -> 0.95 | F39: BELAID (HAFIDA) | G39: JRS | H39: ouvrier | I39: 22 | J39: 100 | K39: 2200 | L39: 25 | M39: 575
G40: JRS | H40: Caporale | I40: 1 | J40: 120 | K40: 120 | L40: 25
B41: RECOLTE | C41: 131 | D41: {=IFERROR(_xlfn.XLOOKUP(C41,Code!A:A,Code!B:B),"")} -> 0.96 | F41: BELAID(NEZHA) | G41: JRS | H41: ouvrier | I41: 11 | J41: 100 | K41: 1100 | L41: 25 | M41: 300
G42: JRS | H42: Caporale | I42: 1 | J42: 120 | K42: 120 | L42: 25
B43: RECOLTE | C43: 127 | D43: {=IFERROR(_xlfn.XLOOKUP(C43,Code!A:A,Code!B:B),"")} -> 0.95 | F43: DRISS(milouda) | G43: JRS | H43: ouvrier | I43: 16
...

Sheet PW002
C1: Suivi Opération Pw002
A6: Operation Date | B6: Operation | C6: Serre | D6: Sup | E6: Trage Transport | F6: Transporteur | G6: type operation | H6: Type Ouvrier | I6: Nb Ouvrier | J6: Prix/Ouvrier | K6: Total | L6: Prix Transport | M6: Transport
A7: 46121 | B7: INSTALATION PALLAIGE | C7: 202 | D7: {=IFERROR(_xlfn.XLOOKUP(C7,Code!A:A,Code!B:B),"")} -> 1.03 | E7: tin farage | F7: tin farage | G7: JRS | H7: ouvrier | I7: 9 | J7: 100 | K7: =I7*J7 -> 900 | L7: 20 | M7: 180
A8: 46122 | B8: INSTALATION PALLAIGE | C8: 204 | D8: {=IFERROR(_xlfn.XLOOKUP(C8,Code!A:A,Code!B:B),"")} -> 0.97 | E8: tin farage | F8: tin farage | H8: ouvrier | I8: 7 | J8: 50 | K8: =I8*J8 -> 350 | L8: 20 | M8: 140
A9: 46126 | B9: NETTOYAGE | C9: 206 | D9: {=IFERROR(_xlfn.XLOOKUP(C9,Code!A:A,Code!B:B),"")} -> 1.02 | E9: AIN QLIAA | F9: AIN QLIAA | G9: JRS | H9: ouvrier | I9: 4 | J9: 110 | K9: =I9*J9 -> 440 | L9: 25 | M9: 100
A10: 46126 | B10: NETTOYAGE | C10: 213 | D10: {=IFERROR(_xlfn.XLOOKUP(C10,Code!A:A,Code!B:B),"")} -> 0.71 | E10: AIN QLIAA | F10: AIN QLIAA | H10: ouvrier | I10: 4 | J10: 105 | K10: =I10*J10 -> 420 | L10: 25 | M10: 100
A11: 46181 | B11: EFFULLAGE | C11: 208 | D11: {=IFERROR(_xlfn.XLOOKUP(C11,Code!A:A,Code!B:B),"")} -> 1.02 | E11: driss (rachida) | G11: JRS | H11: Caporale | I11: 1
C12: 208 | D12: {=IFERROR(_xlfn.XLOOKUP(C12,Code!A:A,Code!B:B),"")} -> 1.02 | H12: ouvrier | I12: 22
A13: 46182 | B13: EFFULLAGE | C13: 209 | D13: {=IFERROR(_xlfn.XLOOKUP(C13,Code!A:A,Code!B:B),"")} -> 1.15 | E13: driss (rachida) | G13: JRS | H13: Caporale | I13: 1
C14: 209 | D14: {=IFERROR(_xlfn.XLOOKUP(C14,Code!A:A,Code!B:B),"")} -> 1.15 | H14: ouvrier | I14: 22
A15: 46183 | B15: EFFULLAGE | C15: 213 | D15: {=IFERROR(_xlfn.XLOOKUP(C15,Code!A:A,Code!B:B),"")} -> 0.71 | E15: driss (rachida) | G15: JRS | H15: Caporale | I15: 1
C16: 217 | D16: {=IFERROR(_xlfn.XLOOKUP(C16,Code!A:A,Code!B:B),"")} -> 0.5 | H16: ouvrier | I16: 20
A17: 46184 | B17: EFFULLAGE | C17: 217 | D17: 1.24 | E17: driss (rachida) | G17: JRS | H17: Caporale | I17: 1
C18: 210 | H18: ouvrier | I18: 22
A19: 46185 | B19: EFFULLAGE | C19: 210 | D19: 1.76 | E19: driss (rachida) | G19: JRS | H19: Caporale | I19: 1
C20: 211 | H20: ouvrier | I20: 24
A21: 46186 | B21: EFFULLAGE | C21: 212 | D21: 3.05 | E21: driss (rachida) | G21: JRS | H21: Caporale | I21: 0
C22: 211 | H22: ouvrier | I22: 19
C23: 214
A24: 46188 | B24: EFFULLAGE | C24: 212 | D24: 1.72 | E24: driss (rachida) | G24: JRS | H24: Caporale | I24: 1
C25: 214 | H25: ouvrier | I25: 23
A27: 46189 | B27: PALISSAGE | C27: 214 | D27: 1.01 | E27: driss (rachida) | G27: JRS | H27: Caporale | I27: 1
H28: ouvrier | I28: 20
A30: 46190 | B30: PALISSAGE | C30: 214 | D30: 1.01 | E30: driss (rachida) | G30: JRS | H30: Caporale | I30: 1
H31: ouvrier | I31: 23
A33: 46191 | B33: PALISSAGE | C33: 214 | D33: 1.97 | E33: driss (rachida) | G33: JRS | H33: Caporale | I33: 1
C34: 215 | H34: ouvrier | I34: 23
A36: 46192 | B36: PALISSAGE | C36: 215 | D36: 0.96 | E36: driss (rachida) | G36: JRS | H36: Caporale | I36: 1
H37: ouvrier | I37: 23
A38: 46193 | B38: PALISSAGE | C38: 201 | D38: 0.96 | E38: driss (rachida) | G38: JRS | H38: Caporale | I38: 1
H39: ouvrier | I39: 20
A40: 46194 | B40: PALISSAGE | C40: 202 | D40: 1.03 | E40: driss (rachida) | G40: JRS | H40: Caporale | I40: 1
H41: ouvrier | I41: 21
A42: 46195 | B42: PALISSAGE | C42: 202 | D42: 2 | E42: driss (rachida) | G42: JRS | H42: Caporale | I42: 1
C43: 204 | H43: ouvrier | I43: 17
A44: 46196 | B44: PALISSAGE | C44: 203 | D44: 1.73 | E44: driss (rachida) | G44: JRS | H44: Caporale | I44: 0
B45: PINCEMENT | C45: 204 | H45: ouvrier | I45: 17
A46: 46197 | B46: PALISSAGE | C46: 205 | D46: 2.74 | E46: driss (rachida) | G46: JRS | H46: Caporale | I46: 1
B47: PINCEMENT | C47: 203 | H47: ouvrier | I47: 21
C48: 204
...

Sheet PW003
C1: Suivi Opération par Ha Pw003
A6: Operation Date | B6: Operation | C6: Serre | D6: Sup | E6: Trage Transport | F6: EQUIPE | G6: type operation | H6: Type Ouvrier | I6: Nb Ouvrier | J6: Prix/Ouvrier | K6: Total | L6: prix/trage | M6: Prix Transport
A7: 46165 | B7: RECOLTE | C7: 326 | D7: 0.63 | E7: AIN QLIAA | F7: DRISS (HABIBA) | G7: JRS | H7: Caporale | I7: 1
G8: JRS | H8: ouvrier | I8: 17
A9: 46166 | B9: RECOLTE | C9: 324 | D9: {=IFERROR(_xlfn.XLOOKUP(C9,Code!A:A,Code!B:B),"")} -> 0.87 | E9: AIN QLIAA | F9: DRISS (HABIBA) | G9: JRS | H9: Caporale | I9: 1
G10: JRS | H10: ouvrier | I10: 20
A11: 46167 | B11: RECOLTE | C11: 328 | D11: {=IFERROR(_xlfn.XLOOKUP(C11,Code!A:A,Code!B:B),"")} -> 0.87 | E11: AIN QLIAA | F11: DRISS (HABIBA) | G11: JRS | H11: Caporale | I11: 1
G12: JRS | H12: ouvrier | I12: 22
A13: 46174 | B13: RECOLTE | C13: 322 | D13: {=IFERROR(_xlfn.XLOOKUP(C13,Code!A:A,Code!B:B),"")} -> 1 | E13: AIN QLIAA | F13: DRISS (HABIBA) | G13: JRS | H13: Caporale | I13: 1
G14: JRS | H14: ouvrier | I14: 12
A15: 46175 | B15: RECOLTE | C15: 323 | D15: {=IFERROR(_xlfn.XLOOKUP(C15,Code!A:A,Code!B:B),"")} -> 1.13 | E15: AIN QLIAA | F15: DRISS (HABIBA) | G15: JRS | H15: Caporale | I15: 1
G16: JRS | H16: ouvrier | I16: 16
A17: 46176 | B17: RECOLTE | C17: 324 | D17: {=IFERROR(_xlfn.XLOOKUP(C17,Code!A:A,Code!B:B),"")} -> 0.87 | E17: AIN QLIAA | F17: DRISS (SOUMAYA) | G17: JRS | H17: Caporale | I17: 1
G18: JRS | H18: ouvrier | I18: 11
A19: 46177 | B19: RECOLTE | C19: 325 | D19: {=IFERROR(_xlfn.XLOOKUP(C19,Code!A:A,Code!B:B),"")} -> 0.85 | E19: AIN QLIAA | F19: DRISS (SOUMAYA) | G19: JRS | H19: Caporale | I19: 1
G20: JRS | H20: ouvrier | I20: 14
A21: 46177 | B21: PALISSAGE | C21: 314 | D21: {=IFERROR(_xlfn.XLOOKUP(C21,Code!A:A,Code!B:B),"")} -> 1.13 | E21: AIN QLIAA | F21: DRISS (KARIM) | G21: JRS | H21: Caporale | I21: 1
G22: JRS | H22: ouvrier | I22: 5
A23: 46178 | B23: RECOLTE | C23: 325 | D23: {=IFERROR(_xlfn.XLOOKUP(C23,Code!A:A,Code!B:B),"")} -> 0.85 | E23: AIN QLIAA | F23: DRISS (SOUMAYA) | G23: JRS | H23: Caporale | I23: 1
C24: 326 | D24: {=IFERROR(_xlfn.XLOOKUP(C24,Code!A:A,Code!B:B),"")} -> 0.63 | G24: JRS | H24: ouvrier | I24: 16
A25: 46178 | B25: PALISSAGE | C25: 314 | D25: {=IFERROR(_xlfn.XLOOKUP(C25,Code!A:A,Code!B:B),"")} -> 1.13 | E25: AIN QLIAA | F25: DRISS (KARIM) | G25: JRS | H25: Caporale | I25: 1
G26: JRS | H26: ouvrier | I26: 8
A27: 46178 | B27: PALISSAGE | C27: 314 | D27: {=IFERROR(_xlfn.XLOOKUP(C27,Code!A:A,Code!B:B),"")} -> 1.13 | E27: AIN QLIAA | F27: DRISS (AZIZA) | G27: JRS | H27: Caporale | I27: 1
G28: JRS | H28: ouvrier | I28: 13
A29: 46179 | B29: RECOLTE | C29: 328 | D29: {=IFERROR(_xlfn.XLOOKUP(C29,Code!A:A,Code!B:B),"")} -> 0.87 | E29: AIN QLIAA | F29: DRISS (SOUMAYA) | G29: JRS | H29: Caporale | I29: 1
G30: JRS | H30: ouvrier | I30: 20
A31: 46179 | B31: PALISSAGE | C31: 314 | D31: {=IFERROR(_xlfn.XLOOKUP(C31,Code!A:A,Code!B:B),"")} -> 1.13 | E31: AIN QLIAA | F31: DRISS (KARIM) | G31: JRS | H31: Caporale | I31: 1
G32: JRS | H32: ouvrier | I32: 10
A33: 46181 | B33: RECOLTE | C33: 327 | D33: {=IFERROR(_xlfn.XLOOKUP(C33,Code!A:A,Code!B:B),"")} -> 0.76 | E33: AIN QLIAA | F33: DRISS (SOUMAYA) | G33: JRS | H33: Caporale | I33: 1
B34: RECOLTE | C34: 301 | D34: {=IFERROR(_xlfn.XLOOKUP(C34,Code!A:A,Code!B:B),"")} -> 0.81 | G34: JRS | H34: ouvrier | I34: 16
A35: 46181 | B35: PALISSAGE | C35: 309 | D35: {=IFERROR(_xlfn.XLOOKUP(C35,Code!A:A,Code!B:B),"")} -> 0.75 | E35: AIN QLIAA | F35: DRISS (KARIM) | G35: JRS | H35: Caporale | I35: 1
G36: JRS | H36: ouvrier | I36: 13
A37: 46181 | B37: PALISSAGE | C37: 309 | D37: {=IFERROR(_xlfn.XLOOKUP(C37,Code!A:A,Code!B:B),"")} -> 0.75 | E37: AIN QLIAA | F37: BELAID (HAFIDA) | G37: JRS | H37: Caporale | I37: 1
G38: JRS | H38: ouvrier | I38: 12
A39: 46182 | B39: RECOLTE | C39: 321 | D39: {=IFERROR(_xlfn.XLOOKUP(C39,Code!A:A,Code!B:B),"")} -> 0.97 | E39: AIN QLIAA | F39: DRISS (SOUMAYA) | G39: JRS | H39: Caporale | I39: 1
C40: 322 | D40: {=IFERROR(_xlfn.XLOOKUP(C40,Code!A:A,Code!B:B),"")} -> 1 | G40: JRS | H40: ouvrier | I40: 17
A41: 46182 | B41: RECOLTE | C41: 306 | D41: {=IFERROR(_xlfn.XLOOKUP(C41,Code!A:A,Code!B:B),"")} -> 0.95 | E41: AIN QLIAA | F41: DRISS (KARIM) | G41: JRS | H41: Caporale | I41: 1
G42: JRS | H42: ouvrier | I42: 8
A43: 46182 | B43: PALISSAGE | C43: 323 | D43: {=IFERROR(_xlfn.XLOOKUP(C43,Code!A:A,Code!B:B),"")} -> 1.13 | E43: AIN QLIAA | F43: BELAID (BOUCHRA) | G43: JRS | H43: Caporale | I43: 1
G44: JRS | H44: ouvrier | I44: 15
...

Sheet PW004
C1: Suivi Opération Pw004
A6: Operation Date | B6: Operation | C6: Serre | D6: Sup | E6: Trage Transport | F6: Transporteur | G6: type operation | H6: Type Ouvrier | I6: Nb Ouvrier | J6: Prix/Ouvrier | K6: Total | L6: Prix Transport | M6: Transport | N6: Totale Général
A7: 46137 | B7: RECOLTE | C7: 406 | D7: {=IFERROR(_xlfn.XLOOKUP(C7,Code!A:A,Code!B:B),"")} -> 1.1 | E7: AIN QLIAA | F7: EQUIPE HAYAT (DRISS) | G7: JRS | H7: Caporale | I7: 1
H8: ouvrier | I8: 20
A9: 46142 | B9: RECOLTE | C9: 403 | D9: {=IFERROR(_xlfn.XLOOKUP(C9,Code!A:A,Code!B:B),"")} -> 0.67 | E9: AIN QLIAA | F9: EQUIPE FATIHA (DRISS) | G9: JRS | H9: Caporale | I9: 1
H10: ouvrier | I10: 19
A11: 46143 | B11: RECOLTE | C11: 403 | D11: {=IFERROR(_xlfn.XLOOKUP(C11,Code!A:A,Code!B:B),"")} -> 0.67 | E11: AIN QLIAA | F11: EQUIPE FATIHA (DRISS) | G11: JRS | H11: Caporale | I11: 1
C12: 404 | H12: ouvrier | I12: 37
B13: RECOLTE | C13: 405 | D13: {=IFERROR(_xlfn.XLOOKUP(C13,Code!A:A,Code!B:B),"")} -> 1.23 | E13: AIN QLIAA | F13: EQUIPE HALIMA (DRISS) | G13: JRS | H13: Caporale | I13: 1
H14: ouvrier | I14: 15
B15: RECOLTE | C15: 406 | D15: {=IFERROR(_xlfn.XLOOKUP(C15,Code!A:A,Code!B:B),"")} -> 1.1 | E15: AIN QLIAA | F15: EQUIPE BILAL (BELAID) | G15: JRS | H15: Caporale | I15: 1 | J15: 120 | K15: 2020 | L15: 30 | M15: 600 | N15: =SUM(K15+M15) -> 2620
H16: ouvrier | I16: 19 | J16: 100
B17: RECOLTE | C17: 418 | D17: {=IFERROR(_xlfn.XLOOKUP(C17,Code!A:A,Code!B:B),"")} -> 1.32 | E17: AIN QLIAA | F17: EQUIPE MAJID(DRISS) | G17: JRS | H17: Caporale | I17: 1
H18: ouvrier | I18: 13
B19: CHARGE/DECHARGE | H19: ouvrier | I19: 1
A20: 46144 | B20: RECOLTE | C20: 404 | D20: {=IFERROR(_xlfn.XLOOKUP(C20,Code!A:A,Code!B:B),"")} -> 0.67 | E20: AIN QLIAA | F20: EQUIPE HANANE (DRISS) | G20: JRS | H20: Caporale | I20: 1
H21: ouvrier | I21: 25
B22: RECOLTE | C22: 406 | D22: {=IFERROR(_xlfn.XLOOKUP(C22,Code!A:A,Code!B:B),"")} -> 1.1 | E22: AIN QLIAA | F22: EQUIPE YASSINE (DRISS) | G22: JRS | H22: Caporale | I22: 1
H23: ouvrier | I23: 11
B24: RECOLTE | C24: 418 | D24: {=IFERROR(_xlfn.XLOOKUP(C24,Code!A:A,Code!B:B),"")} -> 1.32 | E24: AIN QLIAA | F24: EQUIPE MAJID(DRISS) | G24: JRS | H24: Caporale | I24: 1
H25: ouvrier | I25: 18
B26: CHARGE/DECHARGE | H26: ouvrier | I26: 2
A27: 46146 | B27: RECOLTE | C27: 418 | D27: {=IFERROR(_xlfn.XLOOKUP(C27,Code!A:A,Code!B:B),"")} -> 1.32 | E27: AIN QLIAA | F27: EQUIPE MAJID(DRISS) | G27: JRS | H27: Caporale | I27: 1
H28: ouvrier | I28: 17
B29: CHARGE/DECHARGE | H29: ouvrier | I29: 2
B30: RECOLTE | C30: 406 | D30: {=IFERROR(_xlfn.XLOOKUP(C30,Code!A:A,Code!B:B),"")} -> 1.1 | E30: AIN QLIAA | F30: EQUIPE BILAL (BELAID) | G30: JRS | H30: Caporale | I30: 1 | J30: 120 | K30: 1420 | L30: 30 | M30: 420 | N30: =SUM(K30+M30) -> 1840
H31: ouvrier | I31: 12 | J31: 100
B32: CHARGE/DECHARGE | H32: ouvrier | I32: 1 | J32: 100
A33: 46147 | B33: RECOLTE | C33: 422 | D33: {=IFERROR(_xlfn.XLOOKUP(C33,Code!A:A,Code!B:B),"")} -> 1.24 | E33: AIN QLIAA | F33: EQUIPE MAJID(DRISS) | G33: JRS | H33: Caporale | I33: 1
H34: ouvrier | I34: 19
B35: CHARGE/DECHARGE | H35: ouvrier | I35: 2
B36: RECOLTE | C36: 406 | D36: {=IFERROR(_xlfn.XLOOKUP(C36,Code!A:A,Code!B:B),"")} -> 1.1 | E36: AIN QLIAA | F36: EQUIPE BILAL (BELAID) | G36: JRS | H36: Caporale | I36: 1 | J36: 120 | K36: 1120 | L36: 30 | M36: 330 | N36: =SUM(K36+M36) -> 1450
H37: ouvrier | I37: 9 | J37: 100
B38: CHARGE/DECHARGE | H38: ouvrier | I38: 1 | J38: 100
B39: RECOLTE | C39: 420 | D39: {=IFERROR(_xlfn.XLOOKUP(C39,Code!A:A,Code!B:B),"")} -> 1.41 | E39: AIN QLIAA | F39: EQUIPE YASSINE (DRISS) | G39: JRS | H39: Caporale | I39: 1
H40: ouvrier | I40: 15
B41: CHARGE/DECHARGE | H41: ouvrier | I41: 1
B42: RECOLTE | C42: 409 | D42: {=IFERROR(_xlfn.XLOOKUP(C42,Code!A:A,Code!B:B),"")} -> 1 | E42: AIN QLIAA | F42: EQUIPE KAMAL (BELAID) | G42: JRS | H42: Caporale | I42: 1 | J42: 120 | K42: 2220 | L42: 30 | M42: 660 | N42: =SUM(K42+M42) -> 2880
H43: ouvrier | I43: 20 | J43: 100
B44: CHARGE/DECHARGE | H44: ouvrier | I44: 1 | J44: 100
...

Sheet PW005
C1: Suivi Opération Pw005
A8: Operation Date | B8: Operation | C8: Serre | D8: Sup | E8: Trage Transport | F8: EQUPE | G8: type operation | H8: Type Ouvrier | I8: Nb Ouvrier | J8: Prix/Ouvrier | K8: Prix/Total | L8: prix/trage | M8: TOTAL
A9: 46177 | B9: RECOLTE | C9: 502 | D9: {=IFERROR(_xlfn.XLOOKUP(C9,Code!A:A,Code!B:B),"")} -> 0.81 | E9: DRISS (hassna) | G9: JRS | H9: Caporale | I9: 1
G10: JRS | H10: ouvrier | I10: 10
A11: 46178 | B11: RECOLTE | C11: 502 | D11: {=IFERROR(_xlfn.XLOOKUP(C11,Code!A:A,Code!B:B),"")} -> 0.81 | E11: AIN QLIAA | F11: BELAID (BOUCHRA) | G11: JRS | H11: Caporale | I11: 1 | J11: 120 | K11: 120 | L11: 25 | M11: 375
G12: JRS | H12: ouvrier | I12: 14 | J12: 100 | K12: 1400
A13: 46179 | B13: RECOLTE | C13: 502 | D13: {=IFERROR(_xlfn.XLOOKUP(C13,Code!A:A,Code!B:B),"")} -> 0.81 | E13: AIN QLIAA | F13: BELAID (BOUCHRA) | G13: JRS | H13: Caporale | I13: 1 | J13: 120 | K13: 120 | L13: 25 | M13: 375
G14: JRS | H14: ouvrier | I14: 13.5 | J14: 100 | K14: 1350
A15: 46181 | B15: RECOLTE | C15: 502 | D15: {=IFERROR(_xlfn.XLOOKUP(C15,Code!A:A,Code!B:B),"")} -> 0.81 | E15: AIN QLIAA | F15: BELAID (BOUCHRA) | G15: JRS | H15: Caporale | I15: 1 | J15: 120 | K15: 120 | L15: 25 | M15: 350
C16: 504 | G16: JRS | H16: ouvrier | I16: 13 | J16: 100 | K16: 1300
A17: 46184 | B17: RECOLTE | C17: 504 | D17: {=IFERROR(_xlfn.XLOOKUP(C17,Code!A:A,Code!B:B),"")} -> 1.04 | E17: AIN QLIAA | F17: BELAID (BOUCHRA) | G17: JRS | H17: Caporale | I17: 1 | J17: 120 | K17: 120 | L17: 25 | M17: 500
G18: JRS | H18: ouvrier | I18: 19 | J18: 100 | K18: 1900
A19: 46185 | B19: RECOLTE | C19: 509 | D19: {=IFERROR(_xlfn.XLOOKUP(C19,Code!A:A,Code!B:B),"")} -> 0.74 | E19: AIN QLIAA | F19: BELAID (BOUCHRA) | G19: JRS | H19: Caporale | I19: 1 | J19: 120 | K19: =I19*120 -> 120 | L19: 25 | M19: =25*22 -> 550
G20: JRS | H20: ouvrier | I20: 21 | J20: 100 | K20: =I20*J20 -> 2100
A21: 46186 | B21: RECOLTE | C21: 508 | D21: {=IFERROR(_xlfn.XLOOKUP(C21,Code!A:A,Code!B:B),"")} -> 1.01 | E21: AIN QLIAA | F21: BELAID (BOUCHRA) | G21: JRS | H21: Caporale | I21: 1 | J21: 120 | K21: =I21*J21 -> 120 | L21: 25 | M21: =21*25 -> 525
G22: JRS | H22: ouvrier | I22: 20 | J22: 100 | K22: =I22*J22 -> 2000
A23: 46188 | B23: SELECTION | C23: 519 | D23: {=IFERROR(_xlfn.XLOOKUP(C23,Code!A:A,Code!B:B),"")} -> 0.87 | E23: AIN QLIAA | F23: BELAID (BOUCHRA) | G23: JRS | H23: Caporale | I23: 1 | J23: 120 | K23: 120 | L23: 25 | M23: 525
G24: JRS | H24: ouvrier | I24: 20 | J24: 100 | K24: 2000
A25: 46189 | B25: SELECTION | C25: 519 | D25: {=IFERROR(_xlfn.XLOOKUP(C25,Code!A:A,Code!B:B),"")} -> 0.87 | E25: AIN QLIAA | F25: BELAID (BOUCHRA) | G25: JRS | H25: Caporale | I25: 1 | J25: 120 | K25: 120 | L25: 25 | M25: 525
G26: JRS | H26: ouvrier | I26: 20 | J26: 100 | K26: 2000
A27: 46190 | B27: SELECTION | C27: 519 | D27: {=IFERROR(_xlfn.XLOOKUP(C27,Code!A:A,Code!B:B),"")} -> 0.87 | E27: AIN QLIAA | F27: BELAID (BOUCHRA) | G27: JRS | H27: Caporale | I27: 1 | J27: 120 | K27: 120 | L27: 25 | M27: 525
C28: 513 | G28: JRS | H28: ouvrier | I28: 20 | J28: 100 | K28: 2000
A29: 46191 | B29: SELECTION | C29: 515 | D29: {=IFERROR(_xlfn.XLOOKUP(C29,Code!A:A,Code!B:B),"")} -> 0.98 | E29: AIN QLIAA | F29: BELAID (BOUCHRA) | G29: JRS | H29: Caporale | I29: 1 | J29: 120 | K29: 120 | L29: 25 | M29: 525
C30: 513 | G30: JRS | H30: ouvrier | I30: 20 | J30: 100 | K30: 2000
A31: 46192 | B31: SELECTION | C31: 515 | D31: {=IFERROR(_xlfn.XLOOKUP(C31,Code!A:A,Code!B:B),"")} -> 0.98 | E31: AIN QLIAA | F31: BELAID (BOUCHRA) | G31: JRS | H31: Caporale | I31: 1 | J31: 120 | K31: 120 | L31: 25 | M31: 525
C32: 514 | G32: JRS | H32: ouvrier | I32: 20 | J32: 100 | K32: 2000
A33: 46193 | B33: SELECTION | C33: 516 | D33: {=IFERROR(_xlfn.XLOOKUP(C33,Code!A:A,Code!B:B),"")} -> 0.73 | E33: AIN QLIAA | F33: BELAID (BOUCHRA) | G33: JRS | H33: Caporale | I33: 1 | J33: 120 | K33: 120 | L33: 25 | M33: 525
C34: 517 | G34: JRS | H34: ouvrier | I34: 20 | J34: 100 | K34: 2000
A35: 46195 | B35: SELECTION | C35: 516 | D35: {=IFERROR(_xlfn.XLOOKUP(C35,Code!A:A,Code!B:B),"")} -> 0.73 | E35: AIN QLIAA | F35: BELAID (BOUCHRA) | G35: JRS | H35: Caporale | I35: 1 | J35: 120 | K35: 120 | L35: 25 | M35: 525
C36: 518 | G36: JRS | H36: ouvrier | I36: 20 | J36: 100 | K36: 2000
A37: 46196 | B37: SELECTION | C37: 519 | D37: {=IFERROR(_xlfn.XLOOKUP(C37,Code!A:A,Code!B:B),"")} -> 0.87 | E37: AIN QLIAA | F37: BELAID (BOUCHRA) | G37: JRS | H37: Caporale | I37: 1 | J37: 120 | K37: 120 | L37: 25 | M37: 525
C38: 518 | G38: JRS | H38: ouvrier | I38: 20 | J38: 100 | K38: 2000
A39: 46197 | B39: SELECTION | C39: 520 | D39: {=IFERROR(_xlfn.XLOOKUP(C39,Code!A:A,Code!B:B),"")} -> 0.89 | E39: AIN QLIAA | F39: BELAID (BOUCHRA) | G39: JRS | H39: Caporale | I39: 1 | J39: 120 | K39: 120 | L39: 25 | M39: 525
C40: 519 | G40: JRS | H40: ouvrier | I40: 20 | J40: 100 | K40: 2000
A41: 46219 | B41: NETTOYAGE FIN COMPAGNE | C41: 501 | F41: CAMARA (BELAID) | G41: HE | H41: ouvrier | I41: 8 | J41: 200 | K41: 2820 | L41: 400 | M41: 3220
H42: Caporale | I42: 1 | J42: 220
D43: 0.78 | H43: ouvrier | I43: 3 | J43: 240
D44: {=IFERROR(_xlfn.XLOOKUP(C44,Code!A:A,Code!B:B),"")} | H44: ouvrier | I44: 1 | J44: 280
A45: 46220 | B45: NETTOYAGE FIN COMPAGNE | C45: 502 | F45: CAMARA (BELAID) | G45: HE | H45: ouvrier | I45: 4 | J45: 200 | K45: 3220 | L45: 400 | M45: 3620
H46: Caporale | I46: 1 | J46: 220
...

Sheet PW006
H3: Suivi Opération Pw006
A6: Operation Date | B6: Operation | C6: Serre | D6: Sup | E6: type operation | F6: Type Ouvrier | G6: prix/jour | H6: total ouvrier | I6: % Avensment | J6: Montant Paye | K6: Trage Transport | L6: Transporteur | M6: Nb Ouvrier | N6: Prix/TRANSPORT | O6: TOTAL GENERAL
A7: 46118 | B7: BILLONNAGE | C7: 613 | D7: 0.96 | E7: JRS | F7: Ouvrier | G7: 100 | H7: 10 | I7: 1 | J7: =G7*H7 -> 1000 | K7: tin farage | M7: 10 | N7: =H7*20 -> 200 | O7: =J7+N7 -> 1200
A8: 46119 | B8: BILLONNAGE | C8: 617 | D8: 0.94 | E8: JRS | F8: Ouvrier | G8: 100 | H8: 11 | I8: 1 | J8: =G8*H8 -> 1100 | K8: tin farage | M8: 11 | N8: =H8*20 -> 220 | O8: =J8+N8 -> 1320
A9: 46120 | B9: NETTOYAGE FIN COMPAGNE | C9: 605 | D9: 0.97 | E9: JRS | F9: Ouvrier | G9: 125 | H9: 2 | I9: 0.8 | J9: =G9*H9 -> 250 | K9: AIT AMIRA | M9: 17 | N9: 400 | O9: =J9+J10+J11+N9 -> 2400
E10: JRS | F10: Ouvrier | G10: 150 | H10: 5 | J10: =G10*H10 -> 750
E11: JRS | F11: Ouvrier | G11: 100 | H11: 10 | J11: =G11*H11 -> 1000
A12: 46121 | B12: NETTOYAGE FIN COMPAGNE | C12: 605 | D12: {=IFERROR(_xlfn.XLOOKUP(C12,Code!A:A,Code!B:B),"")} -> 0.97 | E12: JRS | F12: Ouvrier | G12: 200 | H12: 5 | I12: 1 | J12: =G12*H12 -> 1000 | K12: AIT AMIRA | M12: 5 | N12: 400 | O12: =J12+J13+J14+J15+J16+J17+N12+N13 -> 2980
A13: 46121 | B13: NETTOYAGE FIN COMPAGNE | C13: 620 | D13: {=IFERROR(_xlfn.XLOOKUP(C13,Code!A:A,Code!B:B),"")} -> 0.96 | E13: JRS | F13: Ouvrier | G13: 150 | H13: 4 | I13: 0.5 | J13: =G13*H13 -> 600 | M13: 15
E14: JRS | F14: Ouvrier | G14: 50 | H14: 3 | J14: =G14*H14 -> 150
E15: JRS | F15: Ouvrier | G15: 120 | H15: 1 | J15: =G15*H15 -> 120
E16: JRS | F16: Ouvrier | G16: 110 | H16: 1 | J16: =G16*H16 -> 110
E17: JRS | F17: Ouvrier | G17: 100 | H17: 6 | J17: =G17*H17 -> 600
A18: 46121 | B18: NETTOYAGE FIN COMPAGNE | C18: 609 | D18: {=IFERROR(_xlfn.XLOOKUP(C18,Code!A:A,Code!B:B),"")} -> 0.96 | E18: JRS | F18: Ouvrier | G18: 200 | H18: 2 | I18: 0.4 | J18: =G18*H18 -> 400 | K18: HOWARA | M18: 13 | N18: =13*36 -> 468 | O18: =N18+J18+J19+J20 -> 2068
E19: JRS | F19: Ouvrier | G19: 100 | H19: 9 | J19: =G19*H19 -> 900
E20: JRS | F20: Ouvrier | G20: 150 | H20: 2 | J20: =G20*H20 -> 300
A21: 46122 | B21: ARRACHAGE/FAUCHAGE | C21: 618 | D21: {=IFERROR(_xlfn.XLOOKUP(C21,Code!A:A,Code!B:B),"")} -> 0.96 | E21: JRS | F21: Ouvrier | G21: 120 | H21: 2 | I21: 0.75 | J21: =G21*H21 -> 240 | K21: BENHACHEM MANSOURI | M21: 5 | N21: BENHACHEM MANSOURI | O21: =J21+J22 -> 600
C22: 619 | D22: {=IFERROR(_xlfn.XLOOKUP(C22,Code!A:A,Code!B:B),"")} -> 0.96 | E22: JRS | F22: Ouvrier | G22: 120 | H22: 3 | I22: 1 | J22: =G22*H22 -> 360
A23: 46123 | B23: NETTOYAGE FIN COMPAGNE | C23: 609 | D23: {=IFERROR(_xlfn.XLOOKUP(C23,Code!A:A,Code!B:B),"")} -> 0.96 | E23: JRS | F23: Ouvrier | G23: 60 | H23: 5 | I23: 0.99 | J23: =G23*H23 -> 300 | K23: AIT AMIRA | M23: 18 | N23: 400 | O23: =J23+J24+J25+J26+J27+J28+J29+N23 -> 2610
E24: JRS | F24: Ouvrier | G24: 120 | H24: 3 | J24: =G24*H24 -> 360
E25: JRS | F25: Ouvrier | G25: 130 | H25: 1 | J25: =G25*H25 -> 130
E26: JRS | F26: Ouvrier | G26: 140 | H26: 1 | J26: =G26*H26 -> 140
E27: JRS | F27: Ouvrier | G27: 150 | H27: 6 | J27: =G27*H27 -> 900
E28: JRS | F28: Ouvrier | G28: 180 | H28: 1 | J28: =G28*H28 -> 180
E29: JRS | F29: Ouvrier | G29: 200 | H29: 1 | J29: =G29*H29 -> 200
A30: 46124 | B30: NETTOYAGE FIN COMPAGNE | C30: 609 | D30: {=IFERROR(_xlfn.XLOOKUP(C30,Code!A:A,Code!B:B),"")} -> 0.96 | E30: JRS | F30: Ouvrier | G30: 150 | H30: 1 | I30: 1 | J30: =G30*H30 -> 150 | K30: AIT AMIRA | M30: 1 | N30: 400 | O30: =J30+J31+J32+J33+J34+J35+J36+J37+J38+J39+J40+J41+J42+N30+N31+N36 -> 4640
C31: 610 | D31: {=IFERROR(_xlfn.XLOOKUP(C31,Code!A:A,Code!B:B),"")} -> 0.56 | E31: JRS | F31: Ouvrier | G31: 135 | H31: 2 | I31: 1 | J31: =G31*H31 -> 270 | M31: 11
E32: JRS | F32: Ouvrier | G32: 200 | H32: 2 | J32: =G32*H32 -> 400
E33: JRS | F33: Ouvrier | G33: 120 | H33: 3 | J33: =G33*H33 -> 360
E34: JRS | F34: Ouvrier | G34: 280 | H34: 1 | J34: =G34*H34 -> 280
E35: JRS | F35: Ouvrier | G35: 170 | H35: 3 | J35: =G35*H35 -> 510
C36: 611 | D36: 0.92 | E36: JRS | F36: Ouvrier | G36: 60 | H36: 1 | I36: 0.5 | J36: =G36*H36 -> 60 | M36: 12
E37: JRS | F37: Ouvrier | G37: 300 | H37: 2 | J37: =G37*H37 -> 600
E38: JRS | F38: Ouvrier | G38: 80 | H38: 1 | J38: =G38*H38 -> 80
E39: JRS | F39: Ouvrier | G39: 220 | H39: 1 | J39: =G39*H39 -> 220
E40: JRS | F40: Ouvrier | G40: 110 | H40: 1 | J40: =G40*H40 -> 110
E41: JRS | F41: Ouvrier | G41: 240 | H41: 2 | J41: 480
E42: JRS | F42: Ouvrier | G42: 180 | H42: 4 | J42: 720
A43: 46125 | B43: NETTOYAGE FIN COMPAGNE | C43: 611 | D43: {=IFERROR(_xlfn.XLOOKUP(C43,Code!A:A,Code!B:B),"")} -> 0.92 | E43: JRS | F43: Ouvrier | G43: 120 | H43: 3 | I43: 1 | J43: =G43*H43 -> 360 | K43: AIT AMIRA | M43: 11 | N43: 400 | O43: =J43+J44+J45+J46+J47+J48+N43 -> 2110
E44: JRS | F44: Ouvrier | G44: 130 | H44: 1 | J44: =G44*H44 -> 130
...

Sheet Code
A1: Serre | B1: Supp
A2: 101 | B2: 1.14
A3: 102 | B3: 1.23
A4: 103 | B4: 1.24
A5: 104 | B5: 0.95
A6: 105 | B6: 0.95
A7: 106 | B7: 0.73
A8: 107 | B8: 0.95
A9: 108 | B9: 0.95
A10: 109 | B10: 0.9
A11: 110 | B11: 0.96
A12: 111 | B12: 1.08
A13: 112 | B13: 0.96
... A220: 1104 | B220: 0.97

Sheet recap
D12: Detail
D13: F002-4-2026
D14: Domaine | E14: Total JRS | F14: Montant
D15: Pw001 | E15: 481 | F15: =E15*165.76 -> 79730.56
D16: Pw004 | E16: 41 | F16: =E16*165.76 -> 6796.16
E17: Total | F17: =SUM(F14:F16) -> 86526.72
E18: Ecart F | F18: =F17-86526.72 -> 0
D20: F004-4-2026
D21: Domaine | E21: Total JRS | F21: Montant
D22: PW007 | E22: 103 | F22: =E22*165.76 -> 17073.28
D23: PW004 | E23: 300 | F23: =E23*165.76 -> 49728
D24: PW001 | E24: 559 | F24: =E24*165.76 -> 92659.84
D25: PW003 | E25: 62 | F25: =E25*165.76 -> 10277.12
D26: PW115 | E26: 13 | F26: =E26*165.76 -> 2154.88
D27: TOTAL | F27: =SUM(F22:F26) -> 171893.12
D28: ECART | F28: =F27-171893.12 -> 0
M235: Bouchra | N235: Odoo mod | O235: Odoo conso | P235: tonnage | Q235: budget code
M236: PW001_PLT_2024-08-29_S3 PW001 | N236: PW001_PLT_2024-08-29_S3 PW001 | O236: PW001_PLT_2024-08-29_S3 PW001 | P236: PW001_PLT_2024-08-29_S3 PW001 | Q236: PW001_PLT_2024-08-29_S3 PW001
M237: PW003_PLT_2024-08-26_S9 PW003 | N237: PW003_PLT_2024-08-26_S9 PW003 | O237: PW003_PLT_2024-08-26_S9 PW003 | P237: PW003_PLT_2024-08-26_S9 PW003 | Q237: PW003_PLT_2024-08-26_S9 PW003
M238: PW003_PLT_2024-09-01_S8 PW003 | N238: PW003_PLT_2024-09-01_S8 PW003 | O238: PW003_PLT_2024-09-01_S8 PW003 | P238: PW003_PLT_2024-09-01_S8 PW003 | Q238: PW003_PLT_2024-09-01_S8 PW003
M239: PW003_TOPKAPIA_2024-09-01_S8 PW003 | N239: PW003_TOPKAPIA_2024-09-01_S8 PW003 | P239: PW003_TOPKAPIA_2024-09-01_S8 PW003 | Q239: PW003_TOPKAPIA_2024-09-01_S8 PW003
M240: PW003_PLT_2024-09-08_S10 PW003 | N240: PW003_PLT_2024-09-08_S10 PW003 | O240: PW003_PLT_2024-09-08_S10 PW003 | P240: PW003_PLT_2024-09-08_S10 PW003 | Q240: PW003_PLT_2024-09-08_S10 PW003
M241: PW004_PLT_2025-05-15_S12 PW004 | N241: PW004_PLT_2025-05-15_S12 PW004 | O241: PW004_PLT_2025-05-15_S12 PW004 | P241: PW004_PLT_2025-05-15_S12 PW004 | Q241: PW004_PLT_2025-05-15_S12 PW004
M242: PW004_PLT_2025-05-23_S13 PW004 | N242: PW004_PLT_2025-05-23_S13 PW004 | O242: PW004_PLT_2025-05-23_S13 PW004 | P242: PW004_PLT_2025-05-23_S13 PW004 | Q242: PW004_PLT_2025-05-23_S13 PW004
M243: PW006_PLPROST_2024-12-24_S2 PW06 | N243: PW006_PLPROST_2024-12-24_S2 PW06 | O243: PW006_PLPROST_2024-12-24_S2 PW06 | P243: PW006_PLPROST_2024-12-24_S2 PW06 | Q243: PW006_PLPROST_2024-12-24_S2 PW06
M244: PW006_PLT_2024-12-25_S1 PW06 | N244: PW006_PLT_2024-12-25_S1 PW06 | O244: PW006_PLT_2024-12-25_S1 PW06 | P244: PW006_PLT_2024-12-25_S1 PW06 | Q244: PW006_PLT_2024-12-25_S1 PW06
M245: PW006_PLPROST_2024-12-24_S3 PW06 | N245: PW006_PLPROST_2024-12-24_S3 PW06 | O245: PW006_PLPROST_2024-12-24_S3 PW06 | P245: PW006_PLPROST_2024-12-24_S3 PW06 | Q245: PW006_PLPROST_2024-12-24_S3 PW06
M246: PW006_PLT_2024-12-24_S3 PW06 | N246: PW006_PLT_2024-12-24_S3 PW06 | O246: PW006_PLT_2024-12-24_S3 PW06 | P246: PW006_PLT_2024-12-24_S3 PW06 | Q246: PW006_PLT_2024-12-24_S3 PW06
M247: PW007_PLT_2024-09-24_S1 PW007 | N247: PW007_PLT_2024-09-24_S1 PW007 | O247: PW007_PLT_2024-09-24_S1 PW007 | P247: PW007_PLT_2024-09-24_S1 PW007 | Q247: PW007_PLT_2024-09-24_S1 PW007
M248: PW007_PLT_2024-09-28_S2 PW007 | N248: PW007_PLT_2024-09-28_S2 PW007 | O248: PW007_PLT_2024-09-28_S2 PW007 | P248: PW007_PLT_2024-09-28_S2 PW007 | Q248: PW007_PLT_2024-09-28_S2 PW007
M249: PW008_PLT_2025-02-18_S1 PW008 | N249: PW008_PLT_2025-02-18_S1 PW008 | O249: PW008_PLT_2025-02-18_S1 PW008 | P249: PW008_PLT_2025-02-18_S1 PW008 | Q249: PW008_PLT_2025-02-18_S1 PW008
M250: PW008_PLPROST_2025-02-18_S1 PW008 | N250: PW008_PLPROST_2025-02-18_S1 PW008 | O250: PW008_PLPROST_2025-02-18_S1 PW008 | P250: PW008_PLPROST_2025-02-18_S1 PW008 | Q250: PW008_PLPROST_2025-02-18_S1 PW008
M251: PW008_PLT_2025-02-26_S2 PW008 | N251: PW008_PLT_2025-02-26_S2 PW008 | O251: PW008_PLT_2025-02-26_S2 PW008 | P251: PW008_PLT_2025-02-26_S2 PW008 | Q251: PW008_PLT_2025-02-26_S2 PW008
... M255: PW011_PLT_2025-03-03_S1 PW011 | N255: PW011_PLT_2025-03-03_S1 PW011 | O255: PW011_PLT_2025-03-03_S1 PW011 | P255: PW011_PLT_2025-03-03_S1 PW011 | Q255: PW011_PLT_2025-03-03_S1 PW011
M256: PW001_PYR/DRE_2024-08-29_S3 PW001 | N256: PW001_PLP_2024-08-29_S3 PW001 | P256: PW001_PLP_2024-08-29_S3 PW001 | Q256: PW001_PLP_2024-08-29_S3 PW001
M257: PW004_PLP_2025-05-23_S13 PW004 | N257: PW004_PLP_2025-05-23_S13 PW004 | O257: PW004_PLP_2025-05-23_S13 PW004 | P257: PW004_PLP_2025-05-23_S13 PW004 | Q257: PW004_PLP_2025-05-23_S13 PW004
M258: PW005_PLP_2024-10-21_S2 PW005 | N258: PW005_PLP_2024-10-21_S2 PW005 | O258: PW005_PLP_2024-10-21_S2 PW005 | P258: PW005_PLP_2024-10-21_S2 PW005 | Q258: PW005_PLP_2024-10-21_S2 PW005
M259: PW001_PLRM_2024-07-27_S2 PW001 | N259: PW001_PLRM_2024-07-27_S2 PW001 | O259: PW001_PLRM_2024-07-27_S2 PW001 | P259: PW001_PLRM_2024-07-27_S2 PW001 | Q259: PW001_PLRM_2024-07-27_S2 PW001
M260: PW001_ROLER_2024-07-27_S2 PW001 | N260: PW001_ROLER_2024-07-27_S2 PW001 | O260: PW001_ROLER_2024-07-27_S2 PW001 | P260: PW001_ROLER_2024-07-27_S2 PW001 | Q260: PW001_ROLER_2024-07-27_S2 PW001
M261: PW003_PLRM_2024-09-01_S8 PW003 | N261: PW003_PLRM_2024-09-01_S8 PW003 | O261: PW003_PLRM_2024-09-01_S8 PW003 | P261: PW003_PLRM_2024-09-01_S8 PW003 | Q261: PW003_PLRM_2024-09-01_S8 PW003
...

Sheet PW007
C1: Suivi Opération par Ha Pw007
A6: Operation Date | B6: Operation | C6: Serre | D6: Sup | E6: Trage Transport | F6: EQUPE | G6: type operation | H6: Type Ouvrier | I6: Nb Ouvrier | J6: Prix/Ouvrier | K6: Total | L6: prix/trage | M6: Prix Transport
A7: 46149 | B7: NETTOYAGE | C7: 713 | D7: {=IFERROR(_xlfn.XLOOKUP(C7,Code!A:A,Code!B:B),"")} -> 0.9542 | E7: - | F7: - | G7: JRS | H7: ouvrier | I7: 4 | J7: 100 | K7: 400
A8: 46150 | B8: AUTRES TRAVAUX | C8: 705 | D8: {=IFERROR(_xlfn.XLOOKUP(C8,Code!A:A,Code!B:B),"")} -> 0.7592 | E8: LAKHMIS AIIT AMIRA | F8: BELLAID | G8: JRS | H8: ouvrier | I8: 1 | J8: 100 | K8: 100 | L8: 25 | M8: 275
B9: AUTRES TRAVAUX | C9: 706 | D9: {=IFERROR(_xlfn.XLOOKUP(C9,Code!A:A,Code!B:B),"")} -> 1.6433 | E9: LAKHMIS AIIT AMIRA | F9: BELLAID | G9: JRS | H9: ouvrier | I9: 4 | J9: 100 | K9: 400
B10: AUTRES TRAVAUX | C10: 712 | D10: {=IFERROR(_xlfn.XLOOKUP(C10,Code!A:A,Code!B:B),"")} -> 1.0716 | E10: LAKHMIS AIIT AMIRA | F10: BELLAID | G10: JRS | H10: ouvrier | I10: 4 | J10: 125 | K10: 500
B11: AUTRES TRAVAUX | C11: 714 | D11: {=IFERROR(_xlfn.XLOOKUP(C11,Code!A:A,Code!B:B),"")} -> 0.6449 | E11: LAKHMIS AIIT AMIRA | F11: BELLAID | G11: JRS | H11: ouvrier | I11: 2 | J11: 150 | K11: 300
A12: 46162 | B12: RECOLTE | C12: 703 | D12: {=IFERROR(_xlfn.XLOOKUP(C12,Code!A:A,Code!B:B),"")} -> 1.0074 | E12: LAKHMIS AIIT AMIRA | F12: BELLAID(kamal) | G12: JRS | H12: ouvrier | I12: 15 | J12: 100 | K12: 1500 | L12: 30 | M12: 450
B13: AUTRES TRAVAUX | C13: 703 | D13: {=IFERROR(_xlfn.XLOOKUP(C13,Code!A:A,Code!B:B),"")} -> 1.0074 | E13: LAKHMIS AIIT AMIRA | G13: JRS | H13: Caporale | I13: 1 | J13: 120 | K13: 120 | L13: 30 | M13: 30
A14: 46163 | B14: RECOLTE | C14: 703 | D14: {=IFERROR(_xlfn.XLOOKUP(C14,Code!A:A,Code!B:B),"")} -> 1.0074 | E14: LAKHMIS AIIT AMIRA | F14: BELLAID(kamal) | G14: JRS | H14: ouvrier | I14: 19 | J14: 100 | K14: 1900 | L14: 30 | M14: 570
B15: AUTRES TRAVAUX | C15: 703 | D15: {=IFERROR(_xlfn.XLOOKUP(C15,Code!A:A,Code!B:B),"")} -> 1.0074 | E15: LAKHMIS AIIT AMIRA | G15: JRS | H15: Caporale | I15: 1 | J15: 120 | K15: 120 | L15: 30 | M15: 30
A16: 46164 | B16: RECOLTE | C16: 705 | D16: {=IFERROR(_xlfn.XLOOKUP(C16,Code!A:A,Code!B:B),"")} -> 0.7592 | E16: LAKHMIS AIIT AMIRA | F16: BELLAID(kamal) | G16: JRS | H16: ouvrier | I16: 23 | J16: 100 | K16: 2300 | L16: 30 | M16: 690
B17: AUTRES TRAVAUX | C17: 705 | D17: {=IFERROR(_xlfn.XLOOKUP(C17,Code!A:A,Code!B:B),"")} -> 0.7592 | E17: LAKHMIS AIIT AMIRA | G17: JRS | H17: Caporale | I17: 1 | J17: 120 | K17: 120 | L17: 30 | M17: 30
B18: RECOLTE | C18: 705 | D18: {=IFERROR(_xlfn.XLOOKUP(C18,Code!A:A,Code!B:B),"")} -> 0.7592 | E18: LAKHMIS AIIT AMIRA | F18: BELLAID(said) | G18: JRS | H18: ouvrier | I18: 16 | J18: 100 | K18: 1600 | L18: 25 | M18: 400
B19: AUTRES TRAVAUX | C19: 705 | D19: {=IFERROR(_xlfn.XLOOKUP(C19,Code!A:A,Code!B:B),"")} -> 0.7592 | E19: LAKHMIS AIIT AMIRA | G19: JRS | H19: Caporale | I19: 1 | J19: 120 | K19: 120 | L19: 25 | M19: 25
A20: 46165 | B20: RECOLTE | C20: 705 | D20: {=IFERROR(_xlfn.XLOOKUP(C20,Code!A:A,Code!B:B),"")} -> 0.7592 | E20: LAKHMIS AIIT AMIRA | F20: BELLAID(kamal) | G20: JRS | H20: ouvrier | I20: 17 | J20: 100 | K20: 1700 | L20: 30 | M20: 510
B21: AUTRES TRAVAUX | C21: 705 | D21: {=IFERROR(_xlfn.XLOOKUP(C21,Code!A:A,Code!B:B),"")} -> 0.7592 | E21: LAKHMIS AIIT AMIRA | G21: JRS | H21: Caporale | I21: 1 | J21: 120 | K21: 120 | L21: 30 | M21: 30
B22: RECOLTE | C22: 705 | D22: {=IFERROR(_xlfn.XLOOKUP(C22,Code!A:A,Code!B:B),"")} -> 0.7592 | E22: LAKHMIS AIIT AMIRA | F22: BELLAID(said) | G22: JRS | H22: ouvrier | I22: 17 | J22: 100 | K22: 1700 | L22: 25 | M22: 425
B23: AUTRES TRAVAUX | C23: 705 | D23: {=IFERROR(_xlfn.XLOOKUP(C23,Code!A:A,Code!B:B),"")} -> 0.7592 | E23: LAKHMIS AIIT AMIRA | G23: JRS | H23: Caporale | I23: 1 | J23: 1 | K23: 120 | L23: 25 | M23: 25
B24: RECOLTE | C24: 706 | D24: {=IFERROR(_xlfn.XLOOKUP(C24,Code!A:A,Code!B:B),"")} -> 1.6433 | E24: AIN LQLIAA | F24: DRISS(raja) | G24: JRS | H24: ouvrier | I24: 1
B25: AUTRES TRAVAUX | C25: 706 | D25: {=IFERROR(_xlfn.XLOOKUP(C25,Code!A:A,Code!B:B),"")} -> 1.6433 | E25: AIN LQLIAA | G25: JRS | H25: Caporale | I25: 12
A26: 46166 | B26: RECOLTE | C26: 707 | D26: {=IFERROR(_xlfn.XLOOKUP(C26,Code!A:A,Code!B:B),"")} -> 0.6875 | E26: AIN LQLIAA | F26: DRISS(raja) | G26: JRS | H26: ouvrier | I26: 18
B27: CHARGE/DECHARGE | C27: 707 | D27: {=IFERROR(_xlfn.XLOOKUP(C27,Code!A:A,Code!B:B),"")} -> 0.6875 | G27: JRS | H27: ouvrier | I27: 1
B28: AUTRES TRAVAUX | C28: 707 | D28: {=IFERROR(_xlfn.XLOOKUP(C28,Code!A:A,Code!B:B),"")} -> 0.6875 | G28: JRS | H28: Caporale | I28: 1
B29: RECOLTE | C29: 706 | D29: {=IFERROR(_xlfn.XLOOKUP(C29,Code!A:A,Code!B:B),"")} -> 1.6433 | E29: LAKHMIS AIIT AMIRA | F29: BELLAID(kamal) | G29: JRS | H29: ouvrier | I29: 29 | J29: 100 | K29: =SUM(J29*I29) -> 2900 | L29: 30 | M29: =L29*I29 -> 870
B30: CHARGE/DECHARGE | C30: 706 | D30: {=IFERROR(_xlfn.XLOOKUP(C30,Code!A:A,Code!B:B),"")} -> 1.6433 | G30: JRS | H30: ouvrier | I30: 2 | J30: 100 | K30: =SUM(J30*I30) -> 200 | L30: 30 | M30: =L30*I30 -> 60
B31: AUTRES TRAVAUX | C31: 706 | D31: {=IFERROR(_xlfn.XLOOKUP(C31,Code!A:A,Code!B:B),"")} -> 1.6433 | G31: JRS | H31: Caporale | I31: 1 | J31: 120 | K31: =SUM(J31*I31) -> 120 | L31: 30 | M31: =L31*I31 -> 30
B32: RECOLTE | C32: 706 | D32: {=IFERROR(_xlfn.XLOOKUP(C32,Code!A:A,Code!B:B),"")} -> 1.6433 | E32: LAKHMIS AIIT AMIRA | F32: BELLAID(said) | G32: JRS | H32: ouvrier | I32: 17 | J32: 100 | K32: =SUM(J32*I32) -> 1700 | L32: 25 | M32: =L32*I32 -> 425
B33: CHARGE/DECHARGE | C33: 706 | D33: {=IFERROR(_xlfn.XLOOKUP(C33,Code!A:A,Code!B:B),"")} -> 1.6433 | G33: JRS | H33: ouvrier | I33: 1 | J33: 100 | K33: =SUM(J33*I33) -> 100 | L33: 25 | M33: =L33*I33 -> 25
B34: AUTRES TRAVAUX | C34: 706 | D34: {=IFERROR(_xlfn.XLOOKUP(C34,Code!A:A,Code!B:B),"")} -> 1.6433 | G34: JRS | H34: Caporale | I34: 1 | J34: 120 | K34: =SUM(J34*I34) -> 120 | L34: 25 | M34: =L34*I34 -> 25
A35: 46167 | B35: RECOLTE | C35: 707 | D35: {=IFERROR(_xlfn.XLOOKUP(C35,Code!A:A,Code!B:B),"")} -> 0.6875 | E35: LAKHMIS AIIT AMIRA | F35: BELLAID(kamal) | G35: JRS | H35: ouvrier | I35: 14 | J35: 100 | K35: =SUM(J35*I35) -> 1400 | L35: 30 | M35: =L35*I35 -> 420
B36: CHARGE/DECHARGE | C36: 707 | D36: {=IFERROR(_xlfn.XLOOKUP(C36,Code!A:A,Code!B:B),"")} -> 0.6875 | G36: JRS | H36: ouvrier | I36: 1 | J36: 100 | K36: =SUM(J36*I36) -> 100 | L36: 30 | M36: =L36*I36 -> 30
B37: AUTRES TRAVAUX | C37: 707 | D37: {=IFERROR(_xlfn.XLOOKUP(C37,Code!A:A,Code!B:B),"")} -> 0.6875 | G37: JRS | H37: Caporale | I37: 1 | J37: 120 | K37: =SUM(J37*I37) -> 120 | L37: 30 | M37: =L37*I37 -> 30
B38: RECOLTE | C38: 707 | D38: {=IFERROR(_xlfn.XLOOKUP(C38,Code!A:A,Code!B:B),"")} -> 0.6875 | E38: AIN LQLIAA | F38: DRISS(raja) | G38: JRS | H38: ouvrier | I38: 18 | J38: 100 | K38: =SUM(J38*I38) -> 1800 | M38: =L38*I38 -> 0
B39: CHARGE/DECHARGE | C39: 707 | D39: {=IFERROR(_xlfn.XLOOKUP(C39,Code!A:A,Code!B:B),"")} -> 0.6875 | G39: JRS | H39: ouvrier | I39: 1 | J39: 100 | K39: =SUM(J39*I39) -> 100 | M39: =L39*I39 -> 0
B40: AUTRES TRAVAUX | C40: 707 | D40: {=IFERROR(_xlfn.XLOOKUP(C40,Code!A:A,Code!B:B),"")} -> 0.6875 | G40: JRS | H40: Caporale | I40: 1 | J40: 120 | K40: =SUM(J40*I40) -> 120 | M40: =L40*I40 -> 0
B41: RECOLTE | C41: 707 | D41: {=IFERROR(_xlfn.XLOOKUP(C41,Code!A:A,Code!B:B),"")} -> 0.6875 | E41: AIN LQLIAA | F41: BELLAID(hafyda)) | G41: JRS | H41: ouvrier | I41: 18 | J41: 100 | K41: =SUM(J41*I41) -> 1800 | L41: 30 | M41: =L41*I41 -> 540
B42: CHARGE/DECHARGE | C42: 707 | D42: {=IFERROR(_xlfn.XLOOKUP(C42,Code!A:A,Code!B:B),"")} -> 0.6875 | G42: JRS | H42: ouvrier | I42: 0 | J42: 0 | K42: =SUM(J42*I42) -> 0 | L42: 0 | M42: =L42*I42 -> 0
B43: AUTRES TRAVAUX | C43: 707 | D43: {=IFERROR(_xlfn.XLOOKUP(C43,Code!A:A,Code!B:B),"")} -> 0.6875 | G43: JRS | H43: Caporale | I43: 1 | J43: 120 | K43: =SUM(J43*I43) -> 120 | L43: 30 | M43: =L43*I43 -> 30
B44: RECOLTE | C44: 707 | D44: {=IFERROR(_xlfn.XLOOKUP(C44,Code!A:A,Code!B:B),"")} -> 0.6875 | E44: AIN LQLIAA | F44: DRISS(mjid) | G44: JRS | H44: ouvrier | I44: 17 | J44: 10 | K44: =SUM(J44*I44) -> 170 | M44: =L44*I44 -> 0
...

Sheet PW008
C1: Suivi Opération par Ha Pw008
A3: Operation Date | B3: Operation | C3: Serre | D3: Sup | E3: EQUIPE | F3: Type Operation | G3: prix/jour | H3: total ouvrier | I3: OUVRIES | J3: % Avensment | K3: Montant Paye | L3: Trage Transport | M3: Nb Ouvrier | N3: TYPE DE TRANSPORT | O3: Prix/TRANSPORT | P3: TOTAL PAYE | Q3: RECEVOIR UN BON
A4: 46113 | B4: NETTOYAGE FIN COMPAGNE | C4: 807 | F4: JRS | G4: 110 | H4: 17 | I4: OUVRIER | J4: 1 | K4: 1870 | L4: AIT AMIRA | M4: 18 | N4: VOYAGE | O4: 400 | P4: 2400 | Q4: OK
F5: JRS | G5: 130 | H5: 1 | I5: CAPORALE | K5: 130
A6: 46115 | B6: NETTOYAGE FIN COMPAGNE | C6: 807 | F6: JRS | G6: 100 | H6: 11 | I6: OUVRIER | J6: 1 | K6: 1100 | L6: AIT AMIRA | M6: 12 | N6: VOYAGE | O6: 400 | P6: 1662 | Q6: OK
F7: JRS | G7: 100 | H7: 1 | I7: CAPORALE | K7: 100
F8: JRS | G8: 62 | H8: 1 | I8: OUVRIER | K8: 62
A9: 46116 | B9: NETTOYAGE FIN COMPAGNE | C9: 807 | F9: JRS | G9: 100 | H9: 12 | I9: OUVRIER | J9: 1 | K9: 1200 | L9: AIT AMIRA | M9: 13 | N9: VOYAGE | O9: 400 | P9: 1700 | Q9: OK
F10: JRS | G10: 100 | H10: 1 | I10: CAPORALE | J10: 1 | K10: 100
A11: 46117 | B11: NETTOYAGE FIN COMPAGNE | C11: 813 | F11: JRS | G11: 120 | H11: 3 | I11: OUVRIER | J11: 1 | K11: 360 | L11: AIT AMIRA | M11: 12 | N11: VOYAGE | O11: 400 | P11: 1800 | Q11: OK
F12: JRS | G12: 110 | H12: 1 | I12: OUVRIER | K12: 110
F13: JRS | G13: 230 | H13: 1 | I13: OUVRIER | K13: 230
F14: JRS | G14: 100 | H14: 7 | I14: OUVRIER | K14: 700
A15: 46118 | B15: NETTOYAGE FIN COMPAGNE | C15: 813 | F15: JRS | G15: 200 | H15: 5 | I15: OUVRIER | J15: 1 | K15: 1000 | L15: AIT AMIRA | M15: 14 | N15: VOYAGE | O15: 400 | P15: 2500 | Q15: OK
F16: JRS | G16: 150 | H16: 2 | I16: OUVRIER | K16: 300
F17: JRS | G17: 100 | H17: 2 | I17: OUVRIER | K17: 200
F18: JRS | G18: 120 | H18: 5 | I18: OUVRIER | K18: 600
A19: 46119 | B19: NETTOYAGE FIN COMPAGNE | C19: 813 | F19: JRS | G19: 100 | H19: 5 | I19: OUVRIER | J19: 1 | K19: 500 | L19: AIT AMIRA | M19: 6 | N19: VOYAGE | O19: 400 | P19: 1020 | Q19: OK
F20: JRS | G20: 120 | H20: 1 | I20: OUVRIER | K20: 120
A21: 46125 | B21: FIBRE COCO DESTRIBUTION | C21: 805 | F21: JRS | G21: 100 | H21: 11 | I21: OUVRIER | J21: 1 | K21: 1100 | L21: KAMAL QLIAA | M21: 12 | N21: 12*25 | O21: 300 | P21: 1520 | Q21: OK
F22: JRS | G22: 120 | H22: 1 | I22: CAPORALE | K22: 120
A23: 46130 | B23: FIBRE COCO DESTRIBUTION | C23: 807 | F23: JRS | G23: 120 | H23: 10 | I23: OUVRIER | J23: 1 | K23: 1200 | L23: AIT AMIRA | M23: 19 | N23: VOYAGE | O23: 400 | P23: 2530 | Q23: OK
A24: 46130 | B24: BURMISATION | F24: JRS | G24: 130 | H24: 1 | I24: OUVRIER | J24: 1 | K24: 130
A25: 46130 | B25: BURMISATION | F25: JRS | G25: 100 | H25: 8 | I25: OUVRIER | J25: 1 | K25: 800
A26: 46130 | B26: BURMISATION | C26: 806 | F26: JRS | G26: 100 | H26: 3 | I26: OUVRIER | J26: 1 | K26: 300 | L26: PROPRE MOYEN | M26: 0 | N26: -- | O26: 0 | P26: 300 | Q26: OK
A27: 46131 | B27: BURMISATION | C27: 809 | F27: JRS | G27: 120 | H27: 5 | I27: OUVRIER | J27: 1 | K27: 600 | L27: AIT AMIRA | M27: 13 | N27: VOYAGE | O27: 400 | P27: 2300 | Q27: OK
A28: 46131 | B28: BURMISATION | C28: 809 | F28: JRS | G28: 150 | H28: 2 | I28: OUVRIER | J28: 1 | K28: 300
A29: 46131 | B29: FIBRE COCO DESTRIBUTION | C29: 809 | F29: JRS | G29: 170 | H29: 5 | I29: OUVRIER | J29: 1 | K29: 850
A30: 46131 | B30: FIBRE COCO DESTRIBUTION | C30: 809 | F30: JRS | G30: 150 | H30: 1 | I30: OUVRIER | J30: 1 | K30: 150
A31: 46132 | B31: BURMISATION | C31: 809 | F31: JRS | G31: 100 | H31: 13 | I31: OUVRIER | J31: 1 | K31: 1300 | L31: KAMAL QLIAA | M31: 17 | N31: 25*17 | O31: 425 | P31: 2095 | Q31: OK
A32: 46132 | B32: BURMISATION | C32: 809 | F32: JRS | G32: 50 | H32: 1 | I32: OUVRIER | J32: 0.5 | K32: 50
A33: 46132 | B33: FIBRE COCO DESTRIBUTION | C33: 809 | F33: JRS | G33: 100 | H33: 2 | I33: OUVRIER | J33: 1 | K33: 200
A34: 46132 | B34: BURMISATION | C34: 809 | F34: JRS | G34: 120 | H34: 1 | I34: CAPORALE | J34: 1 | K34: 120
A35: 46132 | B35: FIBRE COCO DESTRIBUTION | C35: 811 | F35: JRS | G35: 165 | H35: 5 | I35: OUVRIER | J35: 1 | K35: 825 | L35: AIT AMIRA | M35: 20 | N35: VOYAGE | O35: 400 | P35: 3282 | Q35: OK
F36: JRS | G36: 175 | H36: 1 | I36: OUVRIER | J36: 1 | K36: 175
A37: 46132 | B37: BURMISATION | C37: 811 | F37: JRS | G37: 120 | H37: 7 | I37: OUVRIER | J37: 1 | K37: 840
F38: JRS | G38: 150 | H38: 2 | I38: OUVRIER | J38: 1 | K38: 300
F39: JRS | G39: 165 | H39: 1 | I39: OUVRIER | J39: 1 | K39: 165
F40: JRS | G40: 127 | H40: 1 | I40: OUVRIER | J40: 1 | K40: 127
F41: JRS | G41: 150 | H41: 3 | I41: CAPORALE | J41: 1 | K41: 450
...

Sheet PW009
C1: Suivi Opération par Ha Pw 009
H3: SITUATION DES OUVRIERS | M3: SITUATION DES TRANSPORTE
A5: Opération Date | B5: Operation | C5: Serre | D5: Sup | E5: EQUIPE | F5: TRAGE | G5: TYPE OUVRIERS | H5: NB OUVRIERS | I5: CAPORAL | J5: PRIX CAPORAL (DH) | K5: prix / OUVRIERS (DH) | L5: Total (DH) | M5: TRANSPORT | N5: PRIX TRANSPORT (DH) | O5: TOTAL TRANSPORT (DH) | P5: TOTAL PAYÉ (DH)
A6: 46177 | B6: RECOLTE | C6: 906 | D6: {=IFERROR(_xlfn.XLOOKUP(C6,Code!A:A,Code!B:B),"")} -> 0.68 | E6: BELAID (HADDIA) | F6: AIT OUAGMAR | G6: JRS | H6: 7 | I6: 1 | J6: 120 | K6: 100 | L6: =H6*K6+J6 -> 820 | M6: PERSONNE | N6: 20 | O6: =(H6+I6)*N6 -> 160 | P6: =O6+L6 -> 980
A7: 46177 | B7: RECOLTE | C7: 907 | D7: {=IFERROR(_xlfn.XLOOKUP(C7,Code!A:A,Code!B:B),"")} -> 0.64 | E7: DRISS (HABIBA ABBAKHA) | F7: AIT OUAGMAR | H7: 13 | I7: 1 | J7: - | K7: - | L7: - | N7: - | O7: - | P7: -
A8: 46178 | B8: RECOLTE | C8: 906 | D8: {=IFERROR(_xlfn.XLOOKUP(C8,Code!A:A,Code!B:B),"")} -> 0.68 | E8: BELAID (HADDIA) | F8: AIT OUAGMAR | G8: JRS | H8: 8 | I8: 1 | J8: 120 | K8: 100 | L8: =H8*K8 -> 800 | M8: PERSONNE | N8: 20 | O8: =N8*H8 -> 160 | P8: =O8+L8 -> 960
A9: 46178 | B9: RECOLTE | C9: 907 | D9: {=IFERROR(_xlfn.XLOOKUP(C9,Code!A:A,Code!B:B),"")} -> 0.64 | E9: DRISS (HABIBA ABBAKHA) | F9: AIT OUAGMAR | H9: 17 | I9: 1 | J9: - | K9: - | L9: - | N9: - | O9: - | P9: -
A10: 46178 | B10: RECOLTE | C10: 910 | D10: {=IFERROR(_xlfn.XLOOKUP(C10,Code!A:A,Code!B:B),"")} -> 1.17 | E10: DRISS (SMIRA FAHIMI) | F10: AIT OUAGMAR | H10: 11 | I10: 1 | J10: - | K10: - | L10: - | N10: - | O10: - | P10: -
A11: 46179 | B11: RECOLTE | C11: 907 | D11: {=IFERROR(_xlfn.XLOOKUP(C11,Code!A:A,Code!B:B),"")} -> 0.64 | E11: DRISS (HABIBA ABBAKHA) | F11: AIT OUAGMAR | H11: 18 | I11: 1 | J11: - | K11: - | L11: - | N11: - | O11: - | P11: -
A12: 46179 | B12: RECOLTE | C12: 910 | D12: {=IFERROR(_xlfn.XLOOKUP(C12,Code!A:A,Code!B:B),"")} -> 1.17 | E12: DRISS (SMIRA FAHIMI) | F12: AIT OUAGMAR | H12: 15 | I12: 1 | J12: - | K12: - | L12: - | N12: - | O12: - | P12: -
A13: 46180 | B13: RECOLTE | C13: 907 | D13: {=IFERROR(_xlfn.XLOOKUP(C13,Code!A:A,Code!B:B),"")} -> 0.64 | E13: DRISS (HABIBA ABBAKHA) | F13: AIT OUAGMAR | H13: 18 | I13: 1 | J13: - | K13: - | L13: - | N13: - | O13: - | P13: -
A14: 46180 | B14: RECOLTE | C14: 906 | D14: {=IFERROR(_xlfn.XLOOKUP(C14,Code!A:A,Code!B:B),"")} -> 0.68 | E14: DRISS (SMIRA FAHIMI) | F14: AIT OUAGMAR | H14: 24 | I14: 1 | J14: - | K14: - | L14: - | N14: - | O14: - | P14: -
A15: 46181 | B15: RECOLTE | C15: 906 | D15: {=IFERROR(_xlfn.XLOOKUP(C15,Code!A:A,Code!B:B),"")} -> 0.68 | E15: DRISS (SMIRA FAHIMI) | F15: AIT OUAGMAR | H15: 19 | I15: 1 | J15: - | K15: - | L15: - | N15: - | O15: - | P15: -
A16: 46181 | B16: RECOLTE | C16: 912 | D16: {=IFERROR(_xlfn.XLOOKUP(C16,Code!A:A,Code!B:B),"")} -> 0.62 | E16: DRISS (HABIBA ABBAKHA) | F16: AIT OUAGMAR | H16: 19 | I16: 1 | J16: - | K16: - | L16: - | N16: - | O16: - | P16: -
A17: 46182 | B17: RECOLTE | C17: 912 | D17: {=IFERROR(_xlfn.XLOOKUP(C17,Code!A:A,Code!B:B),"")} -> 0.62 | E17: DRISS (HABIBA ABBAKHA) | F17: AIT OUAGMAR | H17: 18 | I17: 1 | J17: - | K17: - | L17: - | N17: - | O17: - | P17: -
A18: 46183 | B18: RECOLTE | C18: 904 | D18: {=IFERROR(_xlfn.XLOOKUP(C18,Code!A:A,Code!B:B),"")} -> 0.96 | E18: DRISS (HABIBA ABBAKHA) | F18: AIT OUAGMAR | H18: 22 | I18: 1 | J18: - | K18: - | L18: - | N18: - | O18: - | P18: -
A19: 46184 | B19: RECOLTE | C19: 904 | D19: {=IFERROR(_xlfn.XLOOKUP(C19,Code!A:A,Code!B:B),"")} -> 0.96 | E19: DRISS (HABIBA ABBAKHA) | F19: AIT OUAGMAR | H19: 24 | I19: 1 | J19: - | K19: - | L19: - | N19: - | O19: - | P19: -
A20: 46185 | B20: RECOLTE | C20: 903 | D20: {=IFERROR(_xlfn.XLOOKUP(C20,Code!A:A,Code!B:B),"")} -> 0.81 | E20: DRISS (HABIBA ABBAKHA) | F20: AIT OUAGMAR | H20: 20 | I20: 1 | J20: - | K20: - | L20: - | N20: - | O20: - | P20: -
... A35: 46203 | B35: RECOLTE | C35: 901 | D35: {=IFERROR(_xlfn.XLOOKUP(C35,Code!A:A,Code!B:B),"")} -> 1.02 | E35: DRISS (HABIBA ABBAKHA) | F35: AIT OUAGMAR | H35: 17 | I35: 1 | J35: - | K35: - | L35: - | N35: - | O35: - | P35: -
A36: 46212 | B36: BILLONNAGE | C36: 914 | D36: {=IFERROR(_xlfn.XLOOKUP(C36,Code!A:A,Code!B:B),"")} -> 0.65 | E36: EQUIPE SAID (BELAID) | G36: PAR "HE" | H36: 11
C37: 915 | D37: {=IFERROR(_xlfn.XLOOKUP(C37,Code!A:A,Code!B:B),"")} -> 0.56
A38: 46214 | B38: NETTOYAGE FIN COMPAGNE | C38: 904 | D38: {=IFERROR(_xlfn.XLOOKUP(C38,Code!A:A,Code!B:B),"")} -> 0.96 | E38: EQUIPE KAMARA (BELAID) | H38: 5 | K38: 220 | L38: =H38*K38+H39*K39+H40*K40 -> 3060 | M38: VOYAGE | O38: 400 | P38: =O38+L38 -> 3460
H39: 5 | K39: 200
H40: 4 | K40: 240
A41: 46215 | B41: NETTOYAGE FIN COMPAGNE | C41: 910 | D41: {=IFERROR(_xlfn.XLOOKUP(C41,Code!A:A,Code!B:B),"")} -> 1.17 | E41: EQUIPE KAMARA (BELAID) | H41: 1 | K41: 220 | L41: =H41*K41+H42*K42+H43*K43 -> 2700 | M41: VOYAGE | O41: 400 | P41: =O41+L41 -> 3100
H42: 4 | K42: 200
H43: 7 | K43: 240
A44: 46215 | B44: BILLONNAGE | C44: 921 | D44: {=IFERROR(_xlfn.XLOOKUP(C44,Code!A:A,Code!B:B),"")} -> 0.64 | E44: EQUIPE SAID (BELAID) | G44: PAR "HE" | H44: 7
C45: 920 | D45: {=IFERROR(_xlfn.XLOOKUP(C45,Code!A:A,Code!B:B),"")} -> 0.59
A46: 46216 | B46: BILLONNAGE | C46: 905 | D46: {=IFERROR(_xlfn.XLOOKUP(C46,Code!A:A,Code!B:B),"")} -> 0.91 | E46: EQUIPE SAID (BELAID) | G46: PAR "HE" | H46: 9
A47: 46216 | B47: NETTOYAGE FIN COMPAGNE | C47: 910 | D47: {=IFERROR(_xlfn.XLOOKUP(C47,Code!A:A,Code!B:B),"")} -> 1.17 | E47: EQUIPE KAMARA (BELAID) | H47: 1 | K47: 220 | L47: =H47*K47+H48*K48+H49*K49 -> 3340 | M47: VOYAGE | O47: 400 | P47: =O47+L47 -> 3740
C48: 911 | D48: {=IFERROR(_xlfn.XLOOKUP(C48,Code!A:A,Code!B:B),"")} -> 0.6 | H48: 6 | K48: 200
H49: 8 | K49: 240
A50: 46217 | B50: BILLONNAGE | C50: 906 | D50: {=IFERROR(_xlfn.XLOOKUP(C50,Code!A:A,Code!B:B),"")} -> 0.68 | E50: EQUIPE SAID (BELAID) | G50: PAR "HE" | H50: 8
C51: 907 | D51: {=IFERROR(_xlfn.XLOOKUP(C51,Code!A:A,Code!B:B),"")} -> 0.64
A52: 46217 | B52: NETTOYAGE FIN COMPAGNE | C52: 911 | D52: {=IFERROR(_xlfn.XLOOKUP(C52,Code!A:A,Code!B:B),"")} -> 0.6 | E52: EQUIPE KAMARA (BELAID) | H52: 5 | K52: 200 | L52: =H52*K52+H53*K53+H54*K54+H55*K55 -> 2860 | M52: VOYAGE | O52: 400 | P52: =O52+L52 -> 3260
C53: 912 | D53: {=IFERROR(_xlfn.XLOOKUP(C53,Code!A:A,Code!B:B),"")} -> 0.62 | H53: 3 | K53: 220
D54: {=IFERROR(_xlfn.XLOOKUP(C54,Code!A:A,Code!B:B),"")} | H54: 3 | K54: 240
D55: {=IFERROR(_xlfn.XLOOKUP(C55,Code!A:A,Code!B:B),"")} | H55: 4 | K55: 120
A56: 46218 | B56: BILLONNAGE | C56: 908 | D56: {=IFERROR(_xlfn.XLOOKUP(C56,Code!A:A,Code!B:B),"")} -> 0.67 | E56: EQUIPE SAID (BELAID) | G56: PAR "HE" | H56: 9
...

Sheet PW010
C1: Suivi Opération Pw010
A5: Operation Date | B5: Operation | C5: Serre | D5: Sup | E5: type operation | F5: Type Ouvrier | G5: prix/jour | H5: total ouvrier | I5: EQUIPE | J5: Montant Paye | K5: Prix/TRANSPORT | L5: TOTAL GENERAL
A6: 46179 | B6: RECOLTE | C6: 1004 | D6: 1.52 | E6: JRS | F6: Ouvrier | G6: 100 | H6: 11 | I6: BELAID(HADIA) | J6: 1100 | K6: 25 | L6: 1520
B7: RECOLTE | E7: JRS | F7: Caporale | G7: 120 | H7: 1 | J7: 120
A8: 46180 | B8: RECOLTE | C8: 1004 | D8: 1.52 | E8: JRS | F8: Ouvrier | G8: 100 | H8: 12 | I8: BELAID(HADIA) | J8: 1200 | K8: 25 | L8: 1645
F9: Caporale | G9: 120 | H9: 1 | J9: 120
A10: 46181 | B10: RECOLTE | C10: 1004 | D10: 1.52 | E10: JRS | F10: Ouvrier | G10: 100 | H10: 10 | I10: BELAID(HADIA) | J10: 1000 | K10: 25
F11: caporale | G11: 120 | H11: 1 | J11: 120
A12: 46182 | B12: RECOLTE | C12: 1004 | D12: 1.52 | E12: JRS | F12: OUvrier | G12: 100 | H12: 13 | I12: BELAID(HADIA) | J12: 1300 | K12: 25
F13: caporale | G13: 120 | H13: 1 | J13: 120
A14: 46183 | B14: RECOLTE | C14: 1004 | D14: 1.52 | E14: JRS | F14: OUVRIER | G14: 100 | H14: 14 | I14: BELAID(HADIA) | J14: 1400 | K14: 25
F15: caporale | G15: 120 | H15: 1 | J15: 120
A16: 46184 | B16: RECOLTE | C16: 1002 | D16: 9.88 | E16: JRS | F16: OUVRIER | G16: 100 | H16: 18 | I16: BELAID(HADIA) | J16: 1800 | K16: 25
F17: caporale | G17: 120 | H17: 1 | J17: 120
A18: 46185 | B18: RECOLTE | C18: 1002 | D18: 9.88 | E18: JRS | F18: OUVRIER | G18: 100 | H18: 19 | I18: BELAID(HADIA) | J18: 1900 | K18: 25
F19: caporale | G19: 120 | H19: 1 | J19: 120
A22: 46248 | B22: RECOLTE | C22: 1007 | E22: JRS | F22: OUVRIER | G22: 100 | H22: 20 | I22: BELAIDI (HAFIDA) | J22: 2000 | K22: 25 | L22: 2645
F23: CAPORAL | G23: 120 | H23: 1 | J23: 120
A24: 46249 | B24: RECOLT+ SELECTION | C24: 1007 | E24: JRS | F24: OUVRIER | G24: 100 | H24: 15 | I24: BELAIDI (HAFIDA) | J24: 1500 | K24: 25 | L24: 2020
F25: CAPORAL | G25: 120 | H25: 1 | J25: 120
A26: 46249 | B26: RECOLT+ SELECTION | C26: 1003 | E26: JRS | F26: OUVRIER | G26: 100 | H26: 14 | I26: BELAIDI (BRAHIM) | J26: 1400 | K26: 25 | L26: 1895
F27: CAPORAL | G27: 120 | H27: 1 | J27: 120
A28: 46250 | B28: RECOLT+ SELECTION | C28: 1003 | E28: JRS | F28: OUVRIER | G28: 100 | H28: 20 | I28: BELAIDI (BRAHIM) | J28: 2000 | K28: 25 | L28: 2645
F29: CAPORAL | G29: 120 | H29: 1 | J29: 120
A30: 46251 | B30: RECOLT+ SELECTION | C30: 1003 | E30: JRS | F30: OUVRIER | G30: 100 | H30: 15 | I30: BELAIDI (BRAHIM) | J30: 1500 | K30: 25 | L30: 2020
F31: CAPORAL | G31: 120 | H31: 1 | J31: 120
A32: 46191 | B32: RECOLT+ SELECTION | C32: 1003 | E32: JRS | F32: OUVRIER | G32: 100 | H32: 18 | I32: BELAIDI (BRAHIM) | J32: 1800 | K32: 25 | L32: 2395
F33: CAPORAL | G33: 120 | H33: 1 | J33: 120
A34: 46253 | B34: RECOLT+ SELECTION | C34: 1005 | E34: JRS | F34: OUVRIER | G34: 100 | H34: 14 | I34: BELAIDI (BRAHIM) | J34: 1400 | K34: 25 | L34: 1895
F35: CAPORAL | G35: 120 | H35: 1 | J35: 120
A36: 46254 | B36: RECOLT+ SELECTION | C36: 1005 | E36: JRS | F36: OUVRIER | G36: 100 | H36: 19 | I36: BELAIDI (BRAHIM) | J36: 1900 | K36: 25 | L36: 2520
F37: CAPORAL | G37: 120 | H37: 1 | J37: 120
A38: 46255 | B38: RECOLT+ SELECTION | C38: 1005 | E38: JRS | F38: OUVRIER | G38: 100 | H38: 17 | I38: BELAIDI (BRAHIM) | J38: 1700 | K38: 25 | L38: 2270
F39: CAPORAL | G39: 120 | H39: 1 | J39: 120
A40: 46256 | B40: RECOLT+ SELECTION | C40: 1005 | E40: JRS | F40: OUVRIER | G40: 100 | H40: 20 | I40: BELAIDI (BRAHIM) | J40: 2000 | K40: 25 | L40: 2645
F41: CAPORAL | G41: 120 | H41: 1 | J41: 120
A42: 46258 | B42: RECOLT+SELECTION | C42: 1007 | E42: JRS | F42: OUVRIER | G42: 100 | H42: 20 | I42: BELAIDI (BRAHIM) | J42: 2000 | K42: 25 | L42: 2645
F43: CAPORAL | G43: 120 | H43: 1 | J43: 120
A44: 46259 | B44: RECOLT+SELECTION | C44: 1007/1006 | E44: JRS | F44: OUVRIER | G44: 100 | H44: 14 | I44: BELAIDI (BRAHIM) | J44: 1400 | K44: 25 | L44: 1895
F45: CAPORAL | G45: 120 | H45: 1 | J45: 120
...

Sheet PW0011
H3: Suivi Opération Pw011
A6: Operation Date | B6: Operation | C6: Serre | D6: Sup | E6: type operation | F6: Type Ouvrier | G6: prix/jour | H6: total ouvrier | I6: % Avensment | J6: Montant Paye | K6: Trage Transport | L6: Transporteur | M6: Nb Ouvrier | N6: Prix/TRANSPORT | O6: TOTAL GENERAL
A7: 46222 | B7: RECOLTE | C7: 1101 | E7: JRS | F7: Ouvrier | G7: 100 | H7: 20 | J7: =G7*H7 -> 2000 | K7: AIN LAQLIAA | L7: EQUIPE BILAL (belaid) | M7: 21 | N7: =M7*30 -> 630 | O7: =J7+J8+N7 -> 2750
E8: JRS | F8: Caporale | G8: 120 | H8: 1 | J8: =G8*H8 -> 120
A9: 46232 | B9: RECOLTE | C9: 1101 | E9: JRS | F9: Ouvrier | G9: 100 | H9: 23 | J9: =G9*H9 -> 2300 | K9: AIN LAQLIAA | L9: EQUIPE RACHIDA (DRISS) | M9: 24
E10: JRS | F10: Caporale | G10: 120 | H10: 1 | J10: =G10*H10 -> 120
A11: 46233 | B11: RECOLTE | C11: 1101 | E11: JRS | F11: Ouvrier | G11: 100 | H11: 23 | J11: =G11*H11 -> 2300 | K11: AIN LAQLIAA | L11: EQUIPE RACHIDA (DRISS) | M11: 24
E12: JRS | F12: Caporale | G12: 120 | H12: 1 | J12: =G12*H12 -> 120
A13: 46234 | B13: RECOLTE | C13: 1101 | E13: JRS | F13: Ouvrier | G13: 100 | H13: 10 | J13: =G13*H13 -> 1000 | K13: AIN LAQLIAA | L13: EQUIPE RACHIDA (DRISS) | M13: 23
B14: CHARGE/DECHARGE | G14: 100 | H14: 2 | J14: 200
B15: PINCEMENT | E15: JRS | F15: Ouvrier | G15: 100 | H15: 10 | J15: 1000
B16: AUTRES TRAVAUX | E16: JRS | F16: Caporale | G16: 120 | H16: 1 | J16: =G16*H16 -> 120
A17: 46235 | B17: RECOLTE | C17: 1103 | E17: JRS | F17: Ouvrier | G17: 100 | H17: 22 | J17: 2200 | K17: AIN LAQLIAA | L17: EQUIPE RACHIDA (DRISS) | M17: 23
E18: JRS | F18: Caporale | G18: 120 | H18: 1 | J18: 120
A19: 46236 | B19: RECOLTE | C19: 1103 | E19: JRS | F19: Ouvrier | G19: 100 | H19: 22 | J19: 2200 | K19: AIN LAQLIAA | L19: EQUIPE RACHIDA (DRISS) | M19: 23
E20: JRS | F20: Caporale | G20: 120 | H20: 1 | J20: 120
A21: 46237 | B21: RECOLTE | C21: 1103 | E21: JRS | F21: Ouvrier | G21: 100 | H21: 20 | J21: 2000 | K21: AIN LAQLIAA | L21: EQUIPE RACHIDA (DRISS) | M21: 22
E22: JRS | F22: Caporale | G22: 120 | H22: 1 | J22: 120
A23: 46238 | B23: RECOLTE | C23: 1103 | E23: JRS | F23: Ouvrier | G23: 100 | H23: 25 | J23: 2500 | K23: AIN LAQLIAA | L23: EQUIPE RACHIDA (DRISS) | M23: 26
E24: JRS | F24: Caporale | G24: 120 | H24: 1 | J24: 120
A25: 46239 | B25: RECOLTE | C25: 1102 | E25: JRS | F25: Ouvrier | G25: 100 | H25: 25 | J25: 2500 | K25: AIN LAQLIAA | L25: EQUIPE RACHIDA (DRISS) | M25: 25
E26: JRS | F26: Caporale | G26: 0 | H26: 0 | J26: 0
A27: 46240 | B27: RECOLTE | C27: 1101 | E27: JRS | F27: Ouvrier | G27: 100 | H27: 24 | J27: 2400 | K27: AIN LAQLIAA | L27: EQUIPE RACHIDA (DRISS) | M27: 25
E28: JRS | F28: Caporale | G28: 120 | H28: 1 | J28: 120
A29: 46247 | B29: RECOLTE | C29: 1104 | E29: JRS | F29: Ouvrier | G29: 100 | H29: 20 | J29: 2000 | K29: AIN LAQLIAA | L29: EQUIPE RACHIDA (DRISS) | M29: 21
E30: JRS | F30: Caporale | G30: 120 | H30: 1 | J30: 120
A31: 46248 | B31: RECOLTE | C31: 1104 | E31: JRS | F31: Ouvrier | G31: 100 | H31: 19 | J31: 1900 | K31: AIN LAQLIAA | L31: EQUIPE RACHIDA (DRISS) | M31: 20
E32: JRS | F32: Caporale | G32: 120 | H32: 1 | J32: 120
A33: 46249 | B33: RECOLTE | C33: 1104 | E33: JRS | F33: Ouvrier | G33: 100 | H33: 20 | J33: 2000 | K33: AIN LAQLIAA | L33: EQUIPE RACHIDA (DRISS) | M33: 21
E34: JRS | F34: Caporale | G34: 120 | H34: 1 | J34: 120
A35: 46261 | B35: RECOLTE | C35: 1101 | E35: JRS | F35: Ouvrier | G35: 100 | H35: 16 | J35: 1600 | K35: AIN LAQLIAA | L35: EQUIPE HADIA (BELAID) | M35: 19 | N35: =M35*30 -> 570 | O35: =J35+J36+N35+J37 -> 2490
